test_reg_ok (test_xzs_reg.MyTestCase) ... ERROR
test_login_err (text_xzs_login.MyTestCase) ... ERROR
test_login_ok (text_xzs_login.MyTestCase) ... ERROR

======================================================================
ERROR: test_reg_ok (test_xzs_reg.MyTestCase)
----------------------------------------------------------------------
Traceback (most recent call last):
  File "C:\Users\Administrator\AppData\Roaming\Python\Python38\site-packages\urllib3\connection.py", line 203, in _new_conn
    sock = connection.create_connection(
  File "C:\Users\Administrator\AppData\Roaming\Python\Python38\site-packages\urllib3\util\connection.py", line 85, in create_connection
    raise err
  File "C:\Users\Administrator\AppData\Roaming\Python\Python38\site-packages\urllib3\util\connection.py", line 73, in create_connection
    sock.connect(sa)
ConnectionRefusedError: [WinError 10061] 由于目标计算机积极拒绝，无法连接。

The above exception was the direct cause of the following exception:

Traceback (most recent call last):
  File "C:\Users\Administrator\AppData\Roaming\Python\Python38\site-packages\urllib3\connectionpool.py", line 790, in urlopen
    response = self._make_request(
  File "C:\Users\Administrator\AppData\Roaming\Python\Python38\site-packages\urllib3\connectionpool.py", line 496, in _make_request
    conn.request(
  File "C:\Users\Administrator\AppData\Roaming\Python\Python38\site-packages\urllib3\connection.py", line 395, in request
    self.endheaders()
  File "D:\python\lib\http\client.py", line 1216, in endheaders
    self._send_output(message_body, encode_chunked=encode_chunked)
  File "D:\python\lib\http\client.py", line 1004, in _send_output
    self.send(msg)
  File "D:\python\lib\http\client.py", line 944, in send
    self.connect()
  File "C:\Users\Administrator\AppData\Roaming\Python\Python38\site-packages\urllib3\connection.py", line 243, in connect
    self.sock = self._new_conn()
  File "C:\Users\Administrator\AppData\Roaming\Python\Python38\site-packages\urllib3\connection.py", line 218, in _new_conn
    raise NewConnectionError(
urllib3.exceptions.NewConnectionError: <urllib3.connection.HTTPConnection object at 0x000001E833E11EB0>: Failed to establish a new connection: [WinError 10061] 由于目标计算机积极拒绝，无法连接。

The above exception was the direct cause of the following exception:

Traceback (most recent call last):
  File "C:\Users\Administrator\AppData\Roaming\Python\Python38\site-packages\requests\adapters.py", line 486, in send
    resp = conn.urlopen(
  File "C:\Users\Administrator\AppData\Roaming\Python\Python38\site-packages\urllib3\connectionpool.py", line 844, in urlopen
    retries = retries.increment(
  File "C:\Users\Administrator\AppData\Roaming\Python\Python38\site-packages\urllib3\util\retry.py", line 515, in increment
    raise MaxRetryError(_pool, url, reason) from reason  # type: ignore[arg-type]
urllib3.exceptions.MaxRetryError: HTTPConnectionPool(host='192.168.55.53', port=8000): Max retries exceeded with url: /api/student/user/register (Caused by NewConnectionError('<urllib3.connection.HTTPConnection object at 0x000001E833E11EB0>: Failed to establish a new connection: [WinError 10061] 由于目标计算机积极拒绝，无法连接。'))

During handling of the above exception, another exception occurred:

Traceback (most recent call last):
  File "D:\2226\apitest26\test_xzs_reg.py", line 15, in test_reg_ok
    r = requests.post(url=self.url,json=data)
  File "C:\Users\Administrator\AppData\Roaming\Python\Python38\site-packages\requests\api.py", line 115, in post
    return request("post", url, data=data, json=json, **kwargs)
  File "C:\Users\Administrator\AppData\Roaming\Python\Python38\site-packages\requests\api.py", line 59, in request
    return session.request(method=method, url=url, **kwargs)
  File "C:\Users\Administrator\AppData\Roaming\Python\Python38\site-packages\requests\sessions.py", line 589, in request
    resp = self.send(prep, **send_kwargs)
  File "C:\Users\Administrator\AppData\Roaming\Python\Python38\site-packages\requests\sessions.py", line 703, in send
    r = adapter.send(request, **kwargs)
  File "C:\Users\Administrator\AppData\Roaming\Python\Python38\site-packages\requests\adapters.py", line 519, in send
    raise ConnectionError(e, request=request)
requests.exceptions.ConnectionError: HTTPConnectionPool(host='192.168.55.53', port=8000): Max retries exceeded with url: /api/student/user/register (Caused by NewConnectionError('<urllib3.connection.HTTPConnection object at 0x000001E833E11EB0>: Failed to establish a new connection: [WinError 10061] 由于目标计算机积极拒绝，无法连接。'))

======================================================================
ERROR: test_login_err (text_xzs_login.MyTestCase)
----------------------------------------------------------------------
Traceback (most recent call last):
  File "C:\Users\Administrator\AppData\Roaming\Python\Python38\site-packages\urllib3\connection.py", line 203, in _new_conn
    sock = connection.create_connection(
  File "C:\Users\Administrator\AppData\Roaming\Python\Python38\site-packages\urllib3\util\connection.py", line 85, in create_connection
    raise err
  File "C:\Users\Administrator\AppData\Roaming\Python\Python38\site-packages\urllib3\util\connection.py", line 73, in create_connection
    sock.connect(sa)
ConnectionRefusedError: [WinError 10061] 由于目标计算机积极拒绝，无法连接。

The above exception was the direct cause of the following exception:

Traceback (most recent call last):
  File "C:\Users\Administrator\AppData\Roaming\Python\Python38\site-packages\urllib3\connectionpool.py", line 790, in urlopen
    response = self._make_request(
  File "C:\Users\Administrator\AppData\Roaming\Python\Python38\site-packages\urllib3\connectionpool.py", line 496, in _make_request
    conn.request(
  File "C:\Users\Administrator\AppData\Roaming\Python\Python38\site-packages\urllib3\connection.py", line 395, in request
    self.endheaders()
  File "D:\python\lib\http\client.py", line 1216, in endheaders
    self._send_output(message_body, encode_chunked=encode_chunked)
  File "D:\python\lib\http\client.py", line 1004, in _send_output
    self.send(msg)
  File "D:\python\lib\http\client.py", line 944, in send
    self.connect()
  File "C:\Users\Administrator\AppData\Roaming\Python\Python38\site-packages\urllib3\connection.py", line 243, in connect
    self.sock = self._new_conn()
  File "C:\Users\Administrator\AppData\Roaming\Python\Python38\site-packages\urllib3\connection.py", line 218, in _new_conn
    raise NewConnectionError(
urllib3.exceptions.NewConnectionError: <urllib3.connection.HTTPConnection object at 0x000001E833D7B5B0>: Failed to establish a new connection: [WinError 10061] 由于目标计算机积极拒绝，无法连接。

The above exception was the direct cause of the following exception:

Traceback (most recent call last):
  File "C:\Users\Administrator\AppData\Roaming\Python\Python38\site-packages\requests\adapters.py", line 486, in send
    resp = conn.urlopen(
  File "C:\Users\Administrator\AppData\Roaming\Python\Python38\site-packages\urllib3\connectionpool.py", line 844, in urlopen
    retries = retries.increment(
  File "C:\Users\Administrator\AppData\Roaming\Python\Python38\site-packages\urllib3\util\retry.py", line 515, in increment
    raise MaxRetryError(_pool, url, reason) from reason  # type: ignore[arg-type]
urllib3.exceptions.MaxRetryError: HTTPConnectionPool(host='192.168.55.1', port=8000): Max retries exceeded with url: /api/user/login (Caused by NewConnectionError('<urllib3.connection.HTTPConnection object at 0x000001E833D7B5B0>: Failed to establish a new connection: [WinError 10061] 由于目标计算机积极拒绝，无法连接。'))

During handling of the above exception, another exception occurred:

Traceback (most recent call last):
  File "D:\2226\apitest26\text_xzs_login.py", line 16, in test_login_err
    r = requests.post(url=self.url, headers=self.header, json=data)
  File "C:\Users\Administrator\AppData\Roaming\Python\Python38\site-packages\requests\api.py", line 115, in post
    return request("post", url, data=data, json=json, **kwargs)
  File "C:\Users\Administrator\AppData\Roaming\Python\Python38\site-packages\requests\api.py", line 59, in request
    return session.request(method=method, url=url, **kwargs)
  File "C:\Users\Administrator\AppData\Roaming\Python\Python38\site-packages\requests\sessions.py", line 589, in request
    resp = self.send(prep, **send_kwargs)
  File "C:\Users\Administrator\AppData\Roaming\Python\Python38\site-packages\requests\sessions.py", line 703, in send
    r = adapter.send(request, **kwargs)
  File "C:\Users\Administrator\AppData\Roaming\Python\Python38\site-packages\requests\adapters.py", line 519, in send
    raise ConnectionError(e, request=request)
requests.exceptions.ConnectionError: HTTPConnectionPool(host='192.168.55.1', port=8000): Max retries exceeded with url: /api/user/login (Caused by NewConnectionError('<urllib3.connection.HTTPConnection object at 0x000001E833D7B5B0>: Failed to establish a new connection: [WinError 10061] 由于目标计算机积极拒绝，无法连接。'))

======================================================================
ERROR: test_login_ok (text_xzs_login.MyTestCase)
----------------------------------------------------------------------
Traceback (most recent call last):
  File "C:\Users\Administrator\AppData\Roaming\Python\Python38\site-packages\urllib3\connection.py", line 203, in _new_conn
    sock = connection.create_connection(
  File "C:\Users\Administrator\AppData\Roaming\Python\Python38\site-packages\urllib3\util\connection.py", line 85, in create_connection
    raise err
  File "C:\Users\Administrator\AppData\Roaming\Python\Python38\site-packages\urllib3\util\connection.py", line 73, in create_connection
    sock.connect(sa)
ConnectionRefusedError: [WinError 10061] 由于目标计算机积极拒绝，无法连接。

The above exception was the direct cause of the following exception:

Traceback (most recent call last):
  File "C:\Users\Administrator\AppData\Roaming\Python\Python38\site-packages\urllib3\connectionpool.py", line 790, in urlopen
    response = self._make_request(
  File "C:\Users\Administrator\AppData\Roaming\Python\Python38\site-packages\urllib3\connectionpool.py", line 496, in _make_request
    conn.request(
  File "C:\Users\Administrator\AppData\Roaming\Python\Python38\site-packages\urllib3\connection.py", line 395, in request
    self.endheaders()
  File "D:\python\lib\http\client.py", line 1216, in endheaders
    self._send_output(message_body, encode_chunked=encode_chunked)
  File "D:\python\lib\http\client.py", line 1004, in _send_output
    self.send(msg)
  File "D:\python\lib\http\client.py", line 944, in send
    self.connect()
  File "C:\Users\Administrator\AppData\Roaming\Python\Python38\site-packages\urllib3\connection.py", line 243, in connect
    self.sock = self._new_conn()
  File "C:\Users\Administrator\AppData\Roaming\Python\Python38\site-packages\urllib3\connection.py", line 218, in _new_conn
    raise NewConnectionError(
urllib3.exceptions.NewConnectionError: <urllib3.connection.HTTPConnection object at 0x000001E833E5C550>: Failed to establish a new connection: [WinError 10061] 由于目标计算机积极拒绝，无法连接。

The above exception was the direct cause of the following exception:

Traceback (most recent call last):
  File "C:\Users\Administrator\AppData\Roaming\Python\Python38\site-packages\requests\adapters.py", line 486, in send
    resp = conn.urlopen(
  File "C:\Users\Administrator\AppData\Roaming\Python\Python38\site-packages\urllib3\connectionpool.py", line 844, in urlopen
    retries = retries.increment(
  File "C:\Users\Administrator\AppData\Roaming\Python\Python38\site-packages\urllib3\util\retry.py", line 515, in increment
    raise MaxRetryError(_pool, url, reason) from reason  # type: ignore[arg-type]
urllib3.exceptions.MaxRetryError: HTTPConnectionPool(host='192.168.55.1', port=8000): Max retries exceeded with url: /api/user/login (Caused by NewConnectionError('<urllib3.connection.HTTPConnection object at 0x000001E833E5C550>: Failed to establish a new connection: [WinError 10061] 由于目标计算机积极拒绝，无法连接。'))

During handling of the above exception, another exception occurred:

Traceback (most recent call last):
  File "D:\2226\apitest26\text_xzs_login.py", line 11, in test_login_ok
    r = requests.post(url=self.url, headers=self.header, json=data)
  File "C:\Users\Administrator\AppData\Roaming\Python\Python38\site-packages\requests\api.py", line 115, in post
    return request("post", url, data=data, json=json, **kwargs)
  File "C:\Users\Administrator\AppData\Roaming\Python\Python38\site-packages\requests\api.py", line 59, in request
    return session.request(method=method, url=url, **kwargs)
  File "C:\Users\Administrator\AppData\Roaming\Python\Python38\site-packages\requests\sessions.py", line 589, in request
    resp = self.send(prep, **send_kwargs)
  File "C:\Users\Administrator\AppData\Roaming\Python\Python38\site-packages\requests\sessions.py", line 703, in send
    r = adapter.send(request, **kwargs)
  File "C:\Users\Administrator\AppData\Roaming\Python\Python38\site-packages\requests\adapters.py", line 519, in send
    raise ConnectionError(e, request=request)
requests.exceptions.ConnectionError: HTTPConnectionPool(host='192.168.55.1', port=8000): Max retries exceeded with url: /api/user/login (Caused by NewConnectionError('<urllib3.connection.HTTPConnection object at 0x000001E833E5C550>: Failed to establish a new connection: [WinError 10061] 由于目标计算机积极拒绝，无法连接。'))

----------------------------------------------------------------------
Ran 3 tests in 3.036s

FAILED (errors=3)
